[2022-01-22 20:54:13,916] {taskinstance.py:670} INFO - Dependencies all met for <TaskInstance: twitter_dag.twitter_sorocaba 2022-01-22T23:53:54.248496+00:00 [queued]>
[2022-01-22 20:54:13,926] {taskinstance.py:670} INFO - Dependencies all met for <TaskInstance: twitter_dag.twitter_sorocaba 2022-01-22T23:53:54.248496+00:00 [queued]>
[2022-01-22 20:54:13,926] {taskinstance.py:880} INFO - 
--------------------------------------------------------------------------------
[2022-01-22 20:54:13,926] {taskinstance.py:881} INFO - Starting attempt 1 of 1
[2022-01-22 20:54:13,926] {taskinstance.py:882} INFO - 
--------------------------------------------------------------------------------
[2022-01-22 20:54:13,937] {taskinstance.py:901} INFO - Executing <Task(TwitterOperator): twitter_sorocaba> on 2022-01-22T23:53:54.248496+00:00
[2022-01-22 20:54:13,941] {standard_task_runner.py:54} INFO - Started process 16239 to run task
[2022-01-22 20:54:13,998] {standard_task_runner.py:77} INFO - Running: ['airflow', 'run', 'twitter_dag', 'twitter_sorocaba', '2022-01-22T23:53:54.248496+00:00', '--job_id', '25', '--pool', 'default_pool', '--raw', '-sd', 'DAGS_FOLDER/twitter_dag.py', '--cfg_path', '/tmp/tmpmj6wvkcv']
[2022-01-22 20:54:13,999] {standard_task_runner.py:78} INFO - Job 25: Subtask twitter_sorocaba
[2022-01-22 20:54:14,019] {logging_mixin.py:112} INFO - Running <TaskInstance: twitter_dag.twitter_sorocaba 2022-01-22T23:53:54.248496+00:00 [running]> on host nicholas-VirtualBox-ubuntu1804
[2022-01-22 20:54:14,057] {base_hook.py:89} INFO - Using connection to: id: twitter_default. Host: https://api.twitter.com, Port: None, Schema: None, Login: None, Password: None, extra: XXXXXXXX
[2022-01-22 20:54:14,060] {twitter_hook.py:37} INFO - URL: https://api.twitter.com/2/tweets/search/recent?query=sorocaba&tweet.fields=author_id,conversation_id,created_at,id,in_reply_to_user_id,public_metrics,text&expansions=author_id&user.fields=id,name,username,created_at&start_time=2022-01-22T23:53:54.00Z&end_time=2022-01-22T23:53:54.00Z
[2022-01-22 20:54:14,061] {http_hook.py:185} WARNING - HTTPSConnectionPool(host='api.twitter.com', port=443): Max retries exceeded with url: /2/tweets/search/recent?query=sorocaba&tweet.fields=author_id,conversation_id,created_at,id,in_reply_to_user_id,public_metrics,text&expansions=author_id&user.fields=id,name,username,created_at&start_time=2022-01-22T23:53:54.00Z&end_time=2022-01-22T23:53:54.00Z (Caused by NewConnectionError('<urllib3.connection.HTTPSConnection object at 0x7fb2a19644e0>: Failed to establish a new connection: [Errno -2] Name or service not known',)) Tenacity will retry to execute the operation
[2022-01-22 20:54:14,062] {taskinstance.py:1150} ERROR - HTTPSConnectionPool(host='api.twitter.com', port=443): Max retries exceeded with url: /2/tweets/search/recent?query=sorocaba&tweet.fields=author_id,conversation_id,created_at,id,in_reply_to_user_id,public_metrics,text&expansions=author_id&user.fields=id,name,username,created_at&start_time=2022-01-22T23:53:54.00Z&end_time=2022-01-22T23:53:54.00Z (Caused by NewConnectionError('<urllib3.connection.HTTPSConnection object at 0x7fb2a19644e0>: Failed to establish a new connection: [Errno -2] Name or service not known',))
Traceback (most recent call last):
  File "/home/nicholas/datapipeline/.env/lib/python3.6/site-packages/urllib3/connection.py", line 160, in _new_conn
    (self._dns_host, self.port), self.timeout, **extra_kw
  File "/home/nicholas/datapipeline/.env/lib/python3.6/site-packages/urllib3/util/connection.py", line 61, in create_connection
    for res in socket.getaddrinfo(host, port, family, socket.SOCK_STREAM):
  File "/usr/lib/python3.6/socket.py", line 745, in getaddrinfo
    for res in _socket.getaddrinfo(host, port, family, type, proto, flags):
socket.gaierror: [Errno -2] Name or service not known

During handling of the above exception, another exception occurred:

Traceback (most recent call last):
  File "/home/nicholas/datapipeline/.env/lib/python3.6/site-packages/urllib3/connectionpool.py", line 677, in urlopen
    chunked=chunked,
  File "/home/nicholas/datapipeline/.env/lib/python3.6/site-packages/urllib3/connectionpool.py", line 381, in _make_request
    self._validate_conn(conn)
  File "/home/nicholas/datapipeline/.env/lib/python3.6/site-packages/urllib3/connectionpool.py", line 978, in _validate_conn
    conn.connect()
  File "/home/nicholas/datapipeline/.env/lib/python3.6/site-packages/urllib3/connection.py", line 309, in connect
    conn = self._new_conn()
  File "/home/nicholas/datapipeline/.env/lib/python3.6/site-packages/urllib3/connection.py", line 172, in _new_conn
    self, "Failed to establish a new connection: %s" % e
urllib3.exceptions.NewConnectionError: <urllib3.connection.HTTPSConnection object at 0x7fb2a19644e0>: Failed to establish a new connection: [Errno -2] Name or service not known

During handling of the above exception, another exception occurred:

Traceback (most recent call last):
  File "/home/nicholas/datapipeline/.env/lib/python3.6/site-packages/requests/adapters.py", line 449, in send
    timeout=timeout
  File "/home/nicholas/datapipeline/.env/lib/python3.6/site-packages/urllib3/connectionpool.py", line 727, in urlopen
    method, url, error=e, _pool=self, _stacktrace=sys.exc_info()[2]
  File "/home/nicholas/datapipeline/.env/lib/python3.6/site-packages/urllib3/util/retry.py", line 446, in increment
    raise MaxRetryError(_pool, url, error or ResponseError(cause))
urllib3.exceptions.MaxRetryError: HTTPSConnectionPool(host='api.twitter.com', port=443): Max retries exceeded with url: /2/tweets/search/recent?query=sorocaba&tweet.fields=author_id,conversation_id,created_at,id,in_reply_to_user_id,public_metrics,text&expansions=author_id&user.fields=id,name,username,created_at&start_time=2022-01-22T23:53:54.00Z&end_time=2022-01-22T23:53:54.00Z (Caused by NewConnectionError('<urllib3.connection.HTTPSConnection object at 0x7fb2a19644e0>: Failed to establish a new connection: [Errno -2] Name or service not known',))

During handling of the above exception, another exception occurred:

Traceback (most recent call last):
  File "/home/nicholas/datapipeline/.env/lib/python3.6/site-packages/airflow/models/taskinstance.py", line 984, in _run_raw_task
    result = task_copy.execute(context=context)
  File "/home/nicholas/datapipeline/airflow/plugins/operators/twitter_operator.py", line 48, in execute
    for pg in hook.run():
  File "/home/nicholas/datapipeline/airflow/plugins/hooks/twitter_hook.py", line 54, in run
    yield from self.paginate(url, session)
  File "/home/nicholas/datapipeline/airflow/plugins/hooks/twitter_hook.py", line 46, in paginate
    data = self.connect_to_endpoint(full_url, session)
  File "/home/nicholas/datapipeline/airflow/plugins/hooks/twitter_hook.py", line 38, in connect_to_endpoint
    return self.run_and_check(session, prep, {}).json()
  File "/home/nicholas/datapipeline/.env/lib/python3.6/site-packages/airflow/hooks/http_hook.py", line 186, in run_and_check
    raise ex
  File "/home/nicholas/datapipeline/.env/lib/python3.6/site-packages/airflow/hooks/http_hook.py", line 178, in run_and_check
    allow_redirects=extra_options.get("allow_redirects", True))
  File "/home/nicholas/datapipeline/.env/lib/python3.6/site-packages/requests/sessions.py", line 643, in send
    r = adapter.send(request, **kwargs)
  File "/home/nicholas/datapipeline/.env/lib/python3.6/site-packages/requests/adapters.py", line 516, in send
    raise ConnectionError(e, request=request)
requests.exceptions.ConnectionError: HTTPSConnectionPool(host='api.twitter.com', port=443): Max retries exceeded with url: /2/tweets/search/recent?query=sorocaba&tweet.fields=author_id,conversation_id,created_at,id,in_reply_to_user_id,public_metrics,text&expansions=author_id&user.fields=id,name,username,created_at&start_time=2022-01-22T23:53:54.00Z&end_time=2022-01-22T23:53:54.00Z (Caused by NewConnectionError('<urllib3.connection.HTTPSConnection object at 0x7fb2a19644e0>: Failed to establish a new connection: [Errno -2] Name or service not known',))
[2022-01-22 20:54:14,063] {taskinstance.py:1194} INFO - Marking task as FAILED. dag_id=twitter_dag, task_id=twitter_sorocaba, execution_date=20220122T235354, start_date=20220122T235413, end_date=20220122T235414
[2022-01-22 20:54:18,914] {local_task_job.py:102} INFO - Task exited with return code 1
